<?xml version="1.0" encoding="utf-8"?>
<!-- This URDF was automatically created by SolidWorks to URDF Exporter! Originally created by Stephen Brawner (brawner@gmail.com) 
     Commit Version: 1.6.0-4-g7f85cfe  Build Version: 1.6.7995.38578
     For more information, please see http://wiki.ros.org/sw_urdf_exporter -->
<robot
  name="inverted_pendulum">
  <link
    name="base_link">
    <inertial>
      <origin
        xyz="-3.26717855560707E-17 -0.00197210793250581 -0.00834319519876685"
        rpy="-1.570796 0 0" />
      <mass
        value="0.0999914801973355" />
      <inertia
        ixx="0.000306925090515305"
        ixy="1.50075261496563E-20"
        ixz="-1.22375042448589E-20"
        iyy="0.000166578860122352"
        iyz="1.64522796127438E-06"
        izz="0.000421608227251848" />
    </inertial>
    <visual>
      <origin
        xyz="0 0 0"
        rpy="0 0 0" />
      <geometry>
        <mesh
          filename="package://inverted_pendulum/meshes/base_link.STL" />
      </geometry>
      <material
        name="">
        <color
          rgba="1 1 1 1" />
      </material>
    </visual>
    <collision>
      <origin
        xyz="0 0 0"
        rpy="0 0 0" />
      <geometry>
        <mesh
          filename="package://inverted_pendulum/meshes/base_link.STL" />
      </geometry>
    </collision>
  </link>
  <link
    name="left_wheel">
    <inertial>
      <origin
        xyz="-1.3878E-17 2.0817E-17 -0.016"
        rpy="0 0 0" />
      <mass
        value="0.05063" />
      <inertia
        ixx="1.0549E-05"
        ixy="-6.3527E-22"
        ixz="-6.1529E-22"
        iyy="1.0549E-05"
        iyz="-2.024E-22"
        izz="1.5654E-05" />
    </inertial>
    <visual>
      <origin
        xyz="0 0 0"
        rpy="0 0 0" />
      <geometry>
        <mesh
          filename="package://inverted_pendulum/meshes/left_wheel.STL" />
      </geometry>
      <material
        name="">
        <color
          rgba="1 1 1 1" />
      </material>
    </visual>
    <collision>
      <origin
        xyz="0 0 0"
        rpy="0 0 0" />
      <geometry>
        <mesh
          filename="package://inverted_pendulum/meshes/left_wheel.STL" />
      </geometry>
    </collision>
  </link>
  <joint
    name="left_wheel_joint"
    type="continuous">
    <origin
      xyz="0.0465 0 -0.0825"
      rpy="1.5708 -1.179 -1.5708" />
    <parent
      link="base_link" />
    <child
      link="left_wheel" />
    <axis
      xyz="0 0 1" />
  </joint>
  <!-- <joint name="left_wheel_joint" type="continuous">
    <origin xyz="0.0465 0 -0.0825" rpy="0 0 0"/>
    <parent link="base_link"/>
    <child link="left_wheel"/>
    <axis xyz="0 1 0"/>
  </joint> -->
  <link
    name="right_wheel">
    <inertial>
      <origin
        xyz="-2.7756E-17 2.0817E-17 -0.016"
        rpy="0 0 0" />
      <mass
        value="0.05063" />
      <inertia
        ixx="1.0549E-05"
        ixy="-1.4823E-21"
        ixz="8.9707E-22"
        iyy="1.0549E-05"
        iyz="-4.2423E-22"
        izz="1.5654E-05" />
    </inertial>
    <visual>
      <origin
        xyz="0 0 0"
        rpy="0 0 0" />
      <geometry>
        <mesh
          filename="package://inverted_pendulum/meshes/right_wheel.STL" />
      </geometry>
      <material
        name="">
        <color
          rgba="1 1 1 1" />
      </material>
    </visual>
    <collision>
      <origin
        xyz="0 0 0"
        rpy="0 0 0" />
      <geometry>
        <mesh
          filename="package://inverted_pendulum/meshes/right_wheel.STL" />
      </geometry>
    </collision>
  </link>
  <joint
    name="right_wheel_joint"
    type="continuous">
    <origin
      xyz="-0.0465 0 -0.0825"
      rpy="1.5708 1.179 1.5708" />
    <parent
      link="base_link" />
    <child
      link="right_wheel" />
    <axis
      xyz="0 0 1" />
  </joint>
  <!-- <joint name="right_wheel_joint" type="continuous">
    <origin xyz="-0.0465 0 -0.0825" rpy="0 0 0"/>
    <parent link="base_link"/>
    <child link="right_wheel"/> 
    <axis xyz="0 1 0"/>
  </joint> -->
  <link
    name="imu_link">
    <inertial>
      <origin xyz="0 0 0" rpy="0 0 0"/>
      <mass value="0.01"/>
      <inertia 
        ixx="0.0001" ixy="0" ixz="0"
        iyy="0.0001" iyz="0" izz="0.0001"/>
    </inertial>
    <visual>
      <origin
        xyz="0 0 0"
        rpy="0 0 0" />
      <geometry>
        <mesh
          filename="package://inverted_pendulum/meshes/imu_link.STL" />
      </geometry>
      <material
        name="">
        <color
          rgba="1 1 1 1" />
      </material>
    </visual>
    <collision>
      <origin
        xyz="0 0 0"
        rpy="0 0 0" />
      <geometry>
        <mesh
          filename="package://inverted_pendulum/meshes/imu_link.STL" />
      </geometry>
    </collision>
  </link>
  <joint
    name="imu_joint"
    type="fixed">
    <origin
      xyz="0 0 -0.076"
      rpy="1.5708 0 0" />
    <parent
      link="base_link" />
    <child
      link="imu_link" />
    <axis
      xyz="0 0 0" />
  </joint>
</robot>